#VRML_SIM R2023b utf8

EXTERNPROTO "https://raw.githubusercontent.com/cyberbotics/webots/R2023b/projects/objects/backgrounds/protos/TexturedBackground.proto"
EXTERNPROTO "https://raw.githubusercontent.com/cyberbotics/webots/R2023b/projects/objects/backgrounds/protos/TexturedBackgroundLight.proto"
EXTERNPROTO "../protos/Floor.proto"
EXTERNPROTO "https://raw.githubusercontent.com/cyberbotics/webots/R2023b/projects/objects/apartment_structure/protos/Wall.proto"
EXTERNPROTO "https://raw.githubusercontent.com/cyberbotics/webots/R2023b/projects/appearances/protos/Roughcast.proto"

WorldInfo {
}
Viewpoint {
  orientation 0.15082703013181017 -0.6803076499801124 -0.7172396450002988 5.683584137841591
  position -2.496059043335472 -4.183639092884516 1.2885672817456504
}
TexturedBackground {
}
TexturedBackgroundLight {
}
Floor {
  size 5 6
  appearance PBRAppearance {
    roughness 1
    metalness 0
  }
}
Robot {
  translation 0.125 -2.25 -0.0597047
  rotation 0.0019671005742989017 0.0021088392015985785 -0.9999958416476302 -1.5707996938995747
  children [
    Camera {
      translation 0.1 0 0.075
      rotation 0 1 0 1.5708003061004252
      name "camera(2)"
    }
    BallJoint {
      jointParameters BallJointParameters {
        position -149373.13930272023
        anchor 0.134677 0 0.07
      }
      jointParameters2 JointParameters {
        position -9.579242953856996
      }
      jointParameters3 JointParameters {
        position 2368.7684281580136
      }
      endPoint Solid {
        translation 0.1347141956016156 0.00020871149278477608 0.07
        rotation 0.12035515870533411 0.170204916689832 0.9780311457758496 4.353408356857884
        children [
          DEF Ball2 Shape {
            appearance PBRAppearance {
              roughness 1
              metalness 0
            }
            geometry Sphere {
              radius 0.01
            }
          }
        ]
        name "solid(6)"
        boundingObject USE Ball2
        physics Physics {
        }
      }
    }
    BallJoint {
      jointParameters BallJointParameters {
        position -41337.21490052491
        anchor 0.065 0 0.07
      }
      jointParameters2 JointParameters {
        position -35.81208330999449
      }
      jointParameters3 JointParameters {
        position 617.852310329578
      }
      endPoint Solid {
        translation 0.065 0 0.07
        rotation 0.09953553355012365 0.9870563825270933 0.12574726745906104 3.2475558769449897
        children [
          DEF Ball Shape {
            appearance PBRAppearance {
              roughness 1
              metalness 0
            }
            geometry Sphere {
              radius 0.01
            }
          }
        ]
        name "solid(5)"
        boundingObject USE Ball
        physics Physics {
        }
      }
    }
    DEF Righteye Solid {
      translation 0.1 -0.05 0.115
      children [
        DistanceSensor {
          rotation 0 0 1 -1.5707996938995747
          name "ds_right"
          lookupTable [
            0 0 0
            0.2 2000 0
          ]
        }
        Shape {
          appearance PBRAppearance {
            baseColor 1 0 0
            roughness 1
            metalness 0
          }
          geometry Box {
            size 0.005 0.005 0.005
          }
        }
      ]
      name "solid(4)"
    }
    DEF FrontEye Solid {
      translation 0.15 0 0.1
      children [
        DistanceSensor {
          name "ds_front"
          lookupTable [
            0 0 0
            0.15 1500 0
          ]
        }
        DEF Eye Shape {
          appearance PBRAppearance {
            baseColor 1 0 0
            roughness 1
            metalness 0
          }
          geometry Box {
            size 0.005 0.005 0.005
          }
        }
        Camera {
          rotation 0 -0.29260772730773377 0.9562325647664395 -1.1780996938995747
          fieldOfView 0.3
        }
        Camera {
          rotation 0 0.29112335093815994 0.9566855254149803 1.1781003061004252
          name "camera(1)"
          fieldOfView 0.3
        }
      ]
      name "solid(2)"
    }
    DEF Lefteye Solid {
      translation 0.1 0.05 0.115
      children [
        DistanceSensor {
          rotation 0 0 1 1.5707996938995747
          name "ds_left"
          lookupTable [
            0 0 0
            0.2 2000 0
          ]
        }
        USE Eye
      ]
      name "solid(3)"
    }
    DEF Body Pose {
      translation 0.1 0 0.09
      rotation 0 1 0 0
      children [
        Shape {
          appearance PBRAppearance {
            roughness 1
          }
          geometry Cylinder {
            height 0.05
            radius 0.05
          }
        }
      ]
    }
    HingeJoint {
      jointParameters HingeJointParameters {
        position 18035.622636908214
        axis 0 1 0
        anchor 0.1 0.056 0.0850021
      }
      device [
        RotationalMotor {
          name "LeftMotor"
          acceleration 1000
          maxVelocity 20
        }
        PositionSensor {
          name "ps_left"
        }
      ]
      endPoint Solid {
        translation 0.09999945853314386 0.056 0.08500412899325868
        rotation 0.8667232236324657 -0.35269676487834245 0.3526979524472715 1.713349995605217
        children [
          DEF Wheel Shape {
            appearance PBRAppearance {
              baseColor 0 0.5 0.8
              roughness 1
              metalness 0.5
            }
            geometry Cylinder {
              height 0.01
              radius 0.025
            }
          }
        ]
        boundingObject USE Wheel
        physics DEF Wheel_physics Physics {
        }
      }
    }
    HingeJoint {
      jointParameters HingeJointParameters {
        position 19517.013004660515
        axis 0 1 0
        anchor 0.1 -0.056 0.0850021
      }
      device [
        RotationalMotor {
          name "RightMotor"
          acceleration 1000
          maxVelocity 20
        }
        PositionSensor {
          name "ps_right"
        }
      ]
      endPoint Solid {
        translation 0.10000056944414057 -0.055999978637257364 0.08499834937733505
        rotation -0.6229713204778422 0.560046533817279 0.5461269209820597 2.035459915427611
        children [
          USE Wheel
        ]
        name "solid(1)"
        boundingObject USE Wheel
        physics USE Wheel_physics
      }
    }
  ]
  boundingObject USE Body
  physics Physics {
  }
  recognitionColors [
    0 0 0
  ]
  controller "Starscream_code"
  controllerArgs [
    ""
  ]
}
Wall {
  translation -2.5 0.5 0
  size 0.01 5 0.1
}
Wall {
  translation 2.5 0.5 0
  name "wall(1)"
  size 0.01 5 0.1
}
Wall {
  translation 0 3 0
  rotation 0 0 1 1.5707996938995747
  name "wall(2)"
  size 0.01 5 0.1
}
Wall {
  translation -1.25 -2 0
  rotation 0 0 1 1.5707996938995747
  name "wall(3)"
  size 0.01 2.5 0.1
}
Wall {
  translation 1.375 -2 0
  rotation 0 0 1 1.5707996938995747
  name "wall(4)"
  size 0.01 2.25 0.1
}
Wall {
  translation -1.625 2.75 0
  rotation 0 0 1 1.5707996938995747
  name "wall(5)"
  size 0.01 1.25 0.1
}
Wall {
  translation 0.125 2.75 0
  rotation 0 0 1 1.5707996938995747
  name "wall(6)"
  size 0.01 0.25 0.1
}
Wall {
  translation 1 2.75 0
  rotation 0 0 1 1.5707996938995747
  name "wall(7)"
  size 0.01 0.5 0.1
}
Wall {
  translation 1.625 2.75 0
  rotation 0 0 1 1.5707996938995747
  name "wall(8)"
  size 0.01 0.25 0.1
}
Wall {
  translation 2.125 2.75 0
  rotation 0 0 1 1.5707996938995747
  name "wall(9)"
  size 0.01 0.25 0.1
}
Wall {
  translation -1.75 2.5 0
  rotation 0 0 1 1.5707996938995747
  name "wall(10)"
  size 0.01 0.5 0.1
}
Wall {
  translation -0.125 2.5 0
  rotation 0 0 1 1.5707996938995747
  name "wall(11)"
  size 0.01 1.75 0.1
}
Wall {
  translation 1.875 2.5 0
  rotation 0 0 1 1.5707996938995747
  name "wall(12)"
  size 0.01 0.25 0.1
}
Wall {
  translation 2.375 2.5 0
  rotation 0 0 1 1.5707996938995747
  name "wall(13)"
  size 0.01 0.25 0.1
}
Wall {
  translation -1.875 2.25 0
  rotation 0 0 1 1.5707996938995747
  name "wall(14)"
  size 0.01 0.25 0.1
}
Wall {
  translation -1.25 2.25 0
  rotation 0 0 1 1.5707996938995747
  name "wall(15)"
  size 0.01 0.5 0.1
}
Wall {
  translation 1.375 2.25 0
  rotation 0 0 1 1.5707996938995747
  name "wall(16)"
  size 0.01 0.25 0.1
}
Wall {
  translation 2.125 2.25 0
  rotation 0 0 1 1.5707996938995747
  name "wall(17)"
  size 0.01 0.75 0.1
}
Wall {
  translation -2.125 2 0
  rotation 0 0 1 1.5707996938995747
  name "wall(18)"
  size 0.01 0.25 0.1
}
Wall {
  translation -1.375 2 0
  rotation 0 0 1 1.5707996938995747
  name "wall(19)"
  size 0.01 0.75 0.1
}
Wall {
  translation 0.625 2 0
  rotation 0 0 1 1.5707996938995747
  name "wall(20)"
  size 0.01 0.25 0.1
}
Wall {
  translation 1.625 2 0
  rotation 0 0 1 1.5707996938995747
  name "wall(21)"
  size 0.01 0.25 0.1
}
Wall {
  translation 2.125 2 0
  rotation 0 0 1 1.5707996938995747
  name "wall(22)"
  size 0.01 0.25 0.1
}
Wall {
  translation -1.875 1.75 0
  rotation 0 0 1 1.5707996938995747
  name "wall(23)"
  size 0.01 0.75 0.1
}
Wall {
  translation -0.625 1.75 0
  rotation 0 0 1 1.5707996938995747
  name "wall(24)"
  size 0.01 0.75 0.1
}
Wall {
  translation 0.375 1.75 0
  rotation 0 0 1 1.5707996938995747
  name "wall(25)"
  size 0.01 0.25 0.1
}
Wall {
  translation 1.125 1.75 0
  rotation 0 0 1 1.5707996938995747
  name "wall(26)"
  size 0.01 0.25 0.1
}
Wall {
  translation 2.125 1.75 0
  rotation 0 0 1 1.5707996938995747
  name "wall(27)"
  size 0.01 0.75 0.1
}
Wall {
  translation -2.25 1.5 0
  rotation 0 0 1 1.5707996938995747
  name "wall(28)"
  size 0.01 0.5 0.1
}
Wall {
  translation -1.125 1.5 0
  rotation 0 0 1 1.5707996938995747
  name "wall(29)"
  size 0.01 0.75 0.1
}
Wall {
  translation -0.125 1.5 0
  rotation 0 0 1 1.5707996938995747
  name "wall(30)"
  size 0.01 0.75 0.1
}
Wall {
  translation 0.75 1.5 0
  rotation 0 0 1 1.5707996938995747
  name "wall(31)"
  size 0.01 0.5 0.1
}
Wall {
  translation -0.375 1.25 0
  rotation 0 0 1 1.5707996938995747
  name "wall(32)"
  size 0.01 0.75 0.1
}
Wall {
  translation 1.125 1.25 0
  rotation 0 0 1 1.5707996938995747
  name "wall(33)"
  size 0.01 0.25 0.1
}
Wall {
  translation 2 1.25 0
  rotation 0 0 1 1.5707996938995747
  name "wall(34)"
  size 0.01 0.5 0.1
}
Wall {
  translation -0.875 1 0
  rotation 0 0 1 1.5707996938995747
  name "wall(35)"
  size 0.01 0.75 0.1
}
Wall {
  translation 0 1 0
  rotation 0 0 1 1.5707996938995747
  name "wall(36)"
  size 0.01 0.5 0.1
}
Wall {
  translation 0.625 1 0
  rotation 0 0 1 1.5707996938995747
  name "wall(37)"
  size 0.01 0.25 0.1
}
Wall {
  translation 1.75 1 0
  rotation 0 0 1 1.5707996938995747
  name "wall(38)"
  size 0.01 0.5 0.1
}
Wall {
  translation 2.375 1 0
  rotation 0 0 1 1.5707996938995747
  name "wall(39)"
  size 0.01 0.25 0.1
}
Wall {
  translation -2.375 0.75 0
  rotation 0 0 1 1.5707996938995747
  name "wall(40)"
  size 0.01 0.25 0.1
}
Wall {
  translation -1.5 0.75 0
  rotation 0 0 1 1.5707996938995747
  name "wall(41)"
  size 0.01 0.5 0.1
}
Wall {
  translation -0.875 0.75 0
  rotation 0 0 1 1.5707996938995747
  name "wall(42)"
  size 0.01 0.25 0.1
}
Wall {
  translation 1 0.75 0
  rotation 0 0 1 1.5707996938995747
  name "wall(43)"
  size 0.01 1 0.1
}
Wall {
  translation 2.125 0.75 0
  rotation 0 0 1 1.5707996938995747
  name "wall(44)"
  size 0.01 0.25 0.1
}
Wall {
  translation -2.125 0.5 0
  rotation 0 0 1 1.5707996938995747
  name "wall(45)"
  size 0.01 0.25 0.1
}
Wall {
  translation -1.25 0.5 0
  rotation 0 0 1 1.5707996938995747
  name "wall(46)"
  size 0.01 0.5 0.1
}
Wall {
  translation -0.625 0.5 0
  rotation 0 0 1 1.5707996938995747
  name "wall(47)"
  size 0.01 0.25 0.1
}
Wall {
  translation 0.375 0.5 0
  rotation 0 0 1 1.5707996938995747
  name "wall(48)"
  size 0.01 0.25 0.1
}
Wall {
  translation 1.25 0.5 0
  rotation 0 0 1 1.5707996938995747
  name "wall(49)"
  size 0.01 1 0.1
}
Wall {
  translation -1.875 0.25 0
  rotation 0 0 1 1.5707996938995747
  name "wall(50)"
  size 0.01 0.75 0.1
}
Wall {
  translation -1.125 0.25 0
  rotation 0 0 1 1.5707996938995747
  name "wall(51)"
  size 0.01 0.25 0.1
}
Wall {
  translation -0.625 0.25 0
  rotation 0 0 1 1.5707996938995747
  name "wall(52)"
  size 0.01 0.25 0.1
}
Wall {
  translation 0.75 0.25 0
  rotation 0 0 1 1.5707996938995747
  name "wall(53)"
  size 0.01 0.5 0.1
}
Wall {
  translation 2 0.25 0
  rotation 0 0 1 1.5707996938995747
  name "wall(54)"
  size 0.01 0.5 0.1
}
Wall {
  translation -1.875 0 0
  rotation 0 0 1 1.5707996938995747
  name "wall(55)"
  size 0.01 0.25 0.1
}
Wall {
  translation -1.375 0 0
  rotation 0 0 1 1.5707996938995747
  name "wall(56)"
  size 0.01 0.25 0.1
}
Wall {
  translation -0.875 0 0
  rotation 0 0 1 1.5707996938995747
  name "wall(57)"
  size 0.01 0.25 0.1
}
Wall {
  translation -0.375 0 0
  rotation 0 0 1 1.5707996938995747
  name "wall(58)"
  size 0.01 0.25 0.1
}
Wall {
  translation 2 0 0
  rotation 0 0 1 1.5707996938995747
  name "wall(59)"
  size 0.01 0.5 0.1
}
Wall {
  translation -2 -0.25 0
  rotation 0 0 1 1.5707996938995747
  name "wall(60)"
  size 0.01 0.5 0.1
}
Wall {
  translation -1 -0.25 0
  rotation 0 0 1 1.5707996938995747
  name "wall(61)"
  size 0.01 0.5 0.1
}
Wall {
  translation 0.25 -0.25 0
  rotation 0 0 1 1.5707996938995747
  name "wall(62)"
  size 0.01 1 0.1
}
Wall {
  translation 1.125 -0.25 0
  rotation 0 0 1 1.5707996938995747
  name "wall(63)"
  size 0.01 0.25 0.1
}
Wall {
  translation 2.125 -0.25 0
  rotation 0 0 1 1.5707996938995747
  name "wall(64)"
  size 0.01 0.25 0.1
}
Wall {
  translation -1.875 -0.5 0
  rotation 0 0 1 1.5707996938995747
  name "wall(65)"
  size 0.01 0.25 0.1
}
Wall {
  translation -1.375 -0.5 0
  rotation 0 0 1 1.5707996938995747
  name "wall(66)"
  size 0.01 0.25 0.1
}
Wall {
  translation 0.5 -0.5 0
  rotation 0 0 1 1.5707996938995747
  name "wall(67)"
  size 0.01 1 0.1
}
Wall {
  translation 1.5 -0.5 0
  rotation 0 0 1 1.5707996938995747
  name "wall(68)"
  size 0.01 0.5 0.1
}
Wall {
  translation 2.375 -0.5 0
  rotation 0 0 1 1.5707996938995747
  name "wall(69)"
  size 0.01 0.25 0.1
}
Wall {
  translation -2.125 -0.75 0
  rotation 0 0 1 1.5707996938995747
  name "wall(70)"
  size 0.01 0.25 0.1
}
Wall {
  translation -1.375 -0.75 0
  rotation 0 0 1 1.5707996938995747
  name "wall(71)"
  size 0.01 0.75 0.1
}
Wall {
  translation -0.375 -0.75 0
  rotation 0 0 1 1.5707996938995747
  name "wall(72)"
  size 0.01 0.75 0.1
}
Wall {
  translation 0.625 -0.75 0
  rotation 0 0 1 1.5707996938995747
  name "wall(73)"
  size 0.01 0.25 0.1
}
Wall {
  translation 1.125 -0.75 0
  rotation 0 0 1 1.5707996938995747
  name "wall(74)"
  size 0.01 0.25 0.1
}
Wall {
  translation 2.125 -0.75 0
  rotation 0 0 1 1.5707996938995747
  name "wall(75)"
  size 0.01 0.25 0.1
}
Wall {
  translation -2.375 -1 0
  rotation 0 0 1 1.5707996938995747
  name "wall(76)"
  size 0.01 0.25 0.1
}
Wall {
  translation -1.625 -1 0
  rotation 0 0 1 1.5707996938995747
  name "wall(77)"
  size 0.01 0.75 0.1
}
Wall {
  translation -0.875 -1 0
  rotation 0 0 1 1.5707996938995747
  name "wall(78)"
  size 0.01 0.25 0.1
}
Wall {
  translation -0.125 -1 0
  rotation 0 0 1 1.5707996938995747
  name "wall(79)"
  size 0.01 0.75 0.1
}
Wall {
  translation 0.75 -1 0
  rotation 0 0 1 1.5707996938995747
  name "wall(80)"
  size 0.01 0.5 0.1
}
Wall {
  translation 1.75 -1 0
  rotation 0 0 1 1.5707996938995747
  name "wall(81)"
  size 0.01 0.5 0.1
}
Wall {
  translation 2.375 -1 0
  rotation 0 0 1 1.5707996938995747
  name "wall(82)"
  size 0.01 0.25 0.1
}
Wall {
  translation 2.375 -1 0
  rotation 0 0 1 1.5707996938995747
  name "wall(83)"
  size 0.01 0.25 0.1
}
Wall {
  translation -2.125 -1.25 0
  rotation 0 0 1 1.5707996938995747
  name "wall(84)"
  size 0.01 0.25 0.1
}
Wall {
  translation -1.25 -1.25 0
  rotation 0 0 1 1.5707996938995747
  name "wall(85)"
  size 0.01 0.5 0.1
}
Wall {
  translation -0.125 -1.25 0
  rotation 0 0 1 1.5707996938995747
  name "wall(86)"
  size 0.01 0.25 0.1
}
Wall {
  translation 1.375 -1.25 0
  rotation 0 0 1 1.5707996938995747
  name "wall(87)"
  size 0.01 0.25 0.1
}
Wall {
  translation 2.125 -1.25 0
  rotation 0 0 1 1.5707996938995747
  name "wall(88)"
  size 0.01 0.25 0.1
}
Wall {
  translation -2.375 -1.5 0
  rotation 0 0 1 1.5707996938995747
  name "wall(89)"
  size 0.01 0.25 0.1
}
Wall {
  translation -1.375 -1.5 0
  rotation 0 0 1 1.5707996938995747
  name "wall(90)"
  size 0.01 0.25 0.1
}
Wall {
  translation -0.75 -1.5 0
  rotation 0 0 1 1.5707996938995747
  name "wall(91)"
  size 0.01 0.5 0.1
}
Wall {
  translation 0.125 -1.5 0
  rotation 0 0 1 1.5707996938995747
  name "wall(92)"
  size 0.01 0.25 0.1
}
Wall {
  translation 0.625 -1.5 0
  rotation 0 0 1 1.5707996938995747
  name "wall(93)"
  size 0.01 0.25 0.1
}
Wall {
  translation 1.125 -1.5 0
  rotation 0 0 1 1.5707996938995747
  name "wall(94)"
  size 0.01 0.25 0.1
}
Wall {
  translation 1.625 -1.5 0
  rotation 0 0 1 1.5707996938995747
  name "wall(95)"
  size 0.01 0.25 0.1
}
Wall {
  translation 2.375 -1.5 0
  rotation 0 0 1 1.5707996938995747
  name "wall(96)"
  size 0.01 0.25 0.1
}
Wall {
  translation -1.75 -1.75 0
  rotation 0 0 1 1.5707996938995747
  name "wall(97)"
  size 0.01 0.5 0.1
}
Wall {
  translation 0 -1.75 0
  rotation 0 0 1 1.5707996938995747
  name "wall(98)"
  size 0.01 1 0.1
}
Wall {
  translation 0.875 -1.75 0
  rotation 0 0 1 1.5707996938995747
  name "wall(99)"
  size 0.01 0.25 0.1
}
Wall {
  translation 1.875 -1.75 0
  rotation 0 0 1 1.5707996938995747
  name "wall(100)"
  size 0.01 0.25 0.1
}
Wall {
  translation -2.25 2.25 0
  name "wall(101)"
  size 0.01 0.5 0.1
}
Wall {
  translation -2.25 1 0
  name "wall(102)"
  size 0.01 0.5 0.1
}
Wall {
  translation -2.25 -0.375 0
  name "wall(103)"
  size 0.01 0.75 0.1
}
Wall {
  translation -2.25 -1.125 0
  name "wall(104)"
  size 0.01 0.25 0.1
}
Wall {
  translation -2.25 -1.625 0
  name "wall(105)"
  size 0.01 0.25 0.1
}
Wall {
  translation -2 1.875 0
  name "wall(106)"
  size 0.01 0.25 0.1
}
Wall {
  translation -2 1 0
  name "wall(107)"
  size 0.01 1 0.1
}
Wall {
  translation -2 0.125 0
  name "wall(108)"
  size 0.01 0.25 0.1
}
Wall {
  translation -2 -0.875 0
  name "wall(109)"
  size 0.01 0.25 0.1
}
Wall {
  translation -2 -1.625 0
  name "wall(110)"
  size 0.01 0.25 0.1
}
Wall {
  translation -1.75 2.125 0
  name "wall(111)"
  size 0.01 0.25 0.1
}
Wall {
  translation -1.75 1 0
  name "wall(112)"
  size 0.01 1.5 0.1
}
Wall {
  translation -1.75 -0.5 0
  name "wall(113)"
  size 0.01 0.5 0.1
}
Wall {
  translation -1.75 -1.375 0
  name "wall(114)"
  size 0.01 0.75 0.1
}
Wall {
  translation -1.5 2.375 0
  name "wall(115)"
  size 0.01 0.25 0.1
}
Wall {
  translation -1.5 1.25 0
  name "wall(116)"
  size 0.01 0.5 0.1
}
Wall {
  translation -1.5 -0.125 0
  name "wall(117)"
  size 0.01 0.75 0.1
}
Wall {
  translation -1.25 2.5 0
  name "wall(118)"
  size 0.01 0.5 0.1
}
Wall {
  translation -1.25 1.625 0
  name "wall(119)"
  size 0.01 0.25 0.1
}
Wall {
  translation -1.25 1 0
  name "wall(120)"
  size 0.01 0.5 0.1
}
Wall {
  translation -1.25 0.375 0
  name "wall(121)"
  size 0.01 0.25 0.1
}
Wall {
  translation -1.25 -0.375 0
  name "wall(122)"
  size 0.01 0.25 0.1
}
Wall {
  translation -1.25 -1.75 0
  name "wall(123)"
  size 0.01 0.5 0.1
}
Wall {
  translation -1 1.875 0
  name "wall(124)"
  size 0.01 0.25 0.1
}
Wall {
  translation -1 1.375 0
  name "wall(125)"
  size 0.01 0.25 0.1
}
Wall {
  translation -1 0.625 0
  name "wall(126)"
  size 0.01 0.25 0.1
}
Wall {
  translation -1 0.125 0
  name "wall(127)"
  size 0.01 0.25 0.1
}
Wall {
  translation -1 0.125 0
  name "wall(128)"
  size 0.01 0.25 0.1
}
Wall {
  translation -1 -0.625 0
  name "wall(129)"
  size 0.01 0.25 0.1
}
Wall {
  translation -1 -1.375 0
  name "wall(130)"
  size 0.01 0.75 0.1
}
Wall {
  translation -0.75 2.625 0
  name "wall(131)"
  size 0.01 0.25 0.1
}
Wall {
  translation -0.75 1.875 0
  name "wall(132)"
  size 0.01 0.75 0.1
}
Wall {
  translation -0.75 1.125 0
  name "wall(133)"
  size 0.01 0.25 0.1
}
Wall {
  translation -0.75 0.625 0
  name "wall(134)"
  size 0.01 0.25 0.1
}
Wall {
  translation -0.75 -1 0
  name "wall(135)"
  size 0.01 0.5 0.1
}
Wall {
  translation -0.75 -1.75 0
  name "wall(136)"
  size 0.01 0.5 0.1
}
Wall {
  translation -0.5 2.875 0
  name "wall(137)"
  size 0.01 0.25 0.1
}
Wall {
  translation -0.5 2.25 0
  name "wall(138)"
  size 0.01 0.5 0.1
}
Wall {
  translation -0.5 0.875 0
  name "wall(139)"
  size 0.01 0.25 0.1
}
Wall {
  translation -0.5 0.375 0
  name "wall(140)"
  size 0.01 0.25 0.1
}
Wall {
  translation -0.5 -0.25 0
  name "wall(141)"
  size 0.01 0.5 0.1
}
Wall {
  translation -0.25 2.625 0
  name "wall(142)"
  size 0.01 0.25 0.1
}
Wall {
  translation -0.25 2 0
  name "wall(143)"
  size 0.01 0.5 0.1
}
Wall {
  translation -0.25 1 0
  name "wall(144)"
  size 0.01 0.5 0.1
}
Wall {
  translation -0.25 0.125 0
  name "wall(145)"
  size 0.01 0.25 0.1
}
Wall {
  translation -0.25 -1.5 0
  name "wall(146)"
  size 0.01 0.5 0.1
}
Wall {
  translation 0 2.875 0
  name "wall(147)"
  size 0.01 0.25 0.1
}
Wall {
  translation 0 1.875 0
  name "wall(148)"
  size 0.01 0.75 0.1
}
Wall {
  translation 0 0.25 0
  name "wall(149)"
  size 0.01 1 0.1
}
Wall {
  translation 0.25 2.125 0
  name "wall(150)"
  size 0.01 0.75 0.1
}
Wall {
  translation 0.25 1.125 0
  name "wall(151)"
  size 0.01 0.75 0.1
}
Wall {
  translation 0.25 0.25 0
  name "wall(152)"
  size 0.01 0.5 0.1
}
Wall {
  translation 0.25 -1 0
  name "wall(153)"
  size 0.01 1 0.1
}
Wall {
  translation 0.25 -1.875 0
  name "wall(154)"
  size 0.01 0.25 0.1
}
Wall {
  translation 0.5 2.625 0
  name "wall(155)"
  size 0.01 0.25 0.1
}
Wall {
  translation 0.5 1.625 0
  name "wall(156)"
  size 0.01 0.25 0.1
}
Wall {
  translation 0.5 1.125 0
  name "wall(157)"
  size 0.01 0.25 0.1
}
Wall {
  translation 0.5 0.5 0
  name "wall(158)"
  size 0.01 0.5 0.1
}
Wall {
  translation 0.5 -0.125 0
  name "wall(159)"
  size 0.01 0.25 0.1
}
Wall {
  translation 0.5 -1.5 0
  name "wall(160)"
  size 0.01 0.5 0.1
}
Wall {
  translation 0.75 2.875 0
  name "wall(161)"
  size 0.01 0.25 0.1
}
Wall {
  translation 0.75 2 0
  name "wall(162)"
  size 0.01 0.5 0.1
}
Wall {
  translation 0.75 1.375 0
  name "wall(163)"
  size 0.01 0.25 0.1
}
Wall {
  translation 0.75 0.125 0
  name "wall(164)"
  size 0.01 0.25 0.1
}
Wall {
  translation 0.75 -0.375 0
  name "wall(165)"
  size 0.01 0.25 0.1
}
Wall {
  translation 0.75 -1 0
  name "wall(166)"
  size 0.01 0.5 0.1
}
Wall {
  translation 1 2.25 0
  name "wall(167)"
  size 0.01 0.5 0.1
}
Wall {
  translation 1 1.25 0
  name "wall(168)"
  size 0.01 0.5 0.1
}
Wall {
  translation 1 0.125 0
  name "wall(169)"
  size 0.01 0.25 0.1
}
Wall {
  translation 1 -1.375 0
  name "wall(170)"
  size 0.01 0.75 0.1
}
Wall {
  translation 1.25 2.625 0
  name "wall(171)"
  size 0.01 0.25 0.1
}
Wall {
  translation 1.25 1.875 0
  name "wall(172)"
  size 0.01 0.25 0.1
}
Wall {
  translation 1.25 1.125 0
  name "wall(173)"
  size 0.01 0.25 0.1
}
Wall {
  translation 1.25 -0.5 0
  name "wall(174)"
  size 0.01 1 0.1
}
Wall {
  translation 1.25 -1.375 0
  name "wall(175)"
  size 0.01 0.25 0.1
}
Wall {
  translation 1.25 -1.8755 0
  name "wall(176)"
  size 0.01 0.25 0.1
}
Wall {
  translation 1.5 2.375 0
  name "wall(177)"
  size 0.01 0.75 0.1
}
Wall {
  translation 1.5 1.625 0
  name "wall(178)"
  size 0.01 0.25 0.1
}
Wall {
  translation 1.5 1 0
  name "wall(179)"
  size 0.01 0.5 0.1
}
Wall {
  translation 1.5 -0.125 0
  name "wall(180)"
  size 0.01 0.75 0.1
}
Wall {
  translation 1.5 -0.875 0
  name "wall(181)"
  size 0.01 0.25 0.1
}
Wall {
  translation 1.5 -1.625 0
  name "wall(182)"
  size 0.01 0.25 0.1
}
Wall {
  translation 1.75 2.125 0
  name "wall(183)"
  size 0.01 0.25 0.1
}
Wall {
  translation 1.75 1.375 0
  name "wall(184)"
  size 0.01 0.25 0.1
}
Wall {
  translation 1.75 0.625 0
  name "wall(185)"
  size 0.01 0.25 0.1
}
Wall {
  translation 1.75 -0.5 0
  name "wall(186)"
  size 0.01 0.5 0.1
}
Wall {
  translation 1.75 -1.25 0
  name "wall(187)"
  size 0.01 0.5 0.1
}
Wall {
  translation 2 2.5 0
  name "wall(188)"
  size 0.01 0.5 0.1
}
Wall {
  translation 2 1.75 0
  name "wall(189)"
  size 0.01 0.5 0.1
}
Wall {
  translation 2 0.625 0
  name "wall(190)"
  size 0.01 0.75 0.1
}
Wall {
  translation 2 -0.125 0
  name "wall(191)"
  size 0.01 0.25 0.1
}
Wall {
  translation 2 -1.375 0
  name "wall(192)"
  size 0.01 0.75 0.1
}
Wall {
  translation 2.25 1.375 0
  name "wall(193)"
  size 0.01 0.25 0.1
}
Wall {
  translation 2.25 0.625 0
  name "wall(194)"
  size 0.01 0.25 0.1
}
Wall {
  translation 2.25 -0.375 0
  name "wall(195)"
  size 0.01 0.25 0.1
}
Wall {
  translation 2.25 -0.875 0
  name "wall(196)"
  size 0.01 0.25 0.1
}
Wall {
  translation 2.25 -1.625 0
  name "wall(197)"
  size 0.01 0.25 0.1
}
Wall {
  translation -0.125 2.25 0
  rotation 0 0 1 1.5707996938995747
  name "wall(198)"
  size 0.01 0.25 0.1
}
Wall {
  translation 0.375 2.25 0
  rotation 0 0 1 1.5707996938995747
  name "wall(199)"
  size 0.01 0.25 0.1
}
Wall {
  translation 0.188909 1.06567 0
  rotation 0 0 1 -0.7853896938995747
  name "survivor-1"
  size 0.01 0.1 0.1
  appearance Roughcast {
    colorOverride 0.33 1 0
    textureTransform TextureTransform {
      scale 2.4 1
    }
  }
}
Wall {
  translation 1.44197 0.794688 0
  rotation 0 0 1 -0.9162953071795865
  name "survivor-2"
  size 0.01 0.1 0.1
  appearance Roughcast {
    colorOverride 0.33 1 0
    textureTransform TextureTransform {
      scale 2.4 1
    }
  }
}
Wall {
  translation 1.69964 -0.569456 0
  rotation 0 0 -1 2.35619
  name "survivor-3"
  size 0.01 0.1 0.1
  appearance Roughcast {
    colorOverride 0.33 1 0
    textureTransform TextureTransform {
      scale 2.4 1
    }
  }
}
Solid {
  translation -0.875 0.125 0.001
  children [
    Group {
      children [
        Pose {
          translation 0 0 0.001
          children [
            Shape {
              appearance PBRAppearance {
                baseColor 1 0.33 0
                metalness 0.4
              }
              geometry Plane {
                size 0.75 0.75
              }
            }
          ]
        }
        Pose {
          translation 0 0 0.002
          children [
            Shape {
              appearance PBRAppearance {
                baseColor 1 0 0
                metalness 0.4
              }
              geometry Plane {
                size 0.25 0.25
              }
            }
          ]
        }
        Shape {
          appearance PBRAppearance {
            baseColor 1 1 0.498
            metalness 0.4
          }
          geometry Plane {
            size 1.25 1.25
          }
          isPickable FALSE
        }
      ]
    }
  ]
  name "FirePit-1"
}
Solid {
  translation -0.365 2.35 0.001
  children [
    Group {
      children [
        Pose {
          translation 0 0 0.001
          children [
            Shape {
              appearance PBRAppearance {
                baseColor 1 0.33 0
                metalness 0.4
              }
              geometry Plane {
                size 0.75 0.75
              }
            }
          ]
        }
        Pose {
          translation 0 0 0.002
          children [
            Shape {
              appearance PBRAppearance {
                baseColor 1 0 0
                metalness 0.4
              }
              geometry Plane {
                size 0.25 0.25
              }
            }
          ]
        }
        Shape {
          appearance PBRAppearance {
            baseColor 1 1 0.498
            metalness 0.4
          }
          geometry Plane {
            size 1.25 1.25
          }
          isPickable FALSE
        }
      ]
    }
  ]
  name "FirePit-2"
}
Solid {
  translation 1.134 -0.875 0.001
  children [
    Group {
      children [
        Pose {
          translation 0 0 0.001
          children [
            Shape {
              appearance PBRAppearance {
                baseColor 1 0.33 0
                metalness 0.4
              }
              geometry Plane {
                size 0.75 0.75
              }
            }
          ]
        }
        Pose {
          translation 0 0 0.002
          children [
            Shape {
              appearance PBRAppearance {
                baseColor 1 0 0
                metalness 0.4
              }
              geometry Plane {
                size 0.25 0.25
              }
            }
          ]
        }
        Shape {
          appearance PBRAppearance {
            baseColor 1 1 0.498
            metalness 0.4
          }
          geometry Plane {
            size 1.25 1.25
          }
          isPickable FALSE
        }
      ]
    }
  ]
  name "FirePit-3"
}
